<?xml version='1.0'?>
<sdf version="1.5">
  <model name="robot_tutorial">
    <static>true</static>
      <!-- The body of the robot and the caster-->
      <link name='chassis'>
        <!-- Inserting the body here -->
        <pose>0 0 .25 0 0 0</pose>   <!-- The geometry origin -->
        <inertial>
          <mass>20.0</mass>
          <pose>-0.1 0 -0.1 0 0 0</pose>
          <inertia>
            <ixx>0.5</ixx>
            <iyy>1.0</iyy>
            <izz>0.1</izz>
          </inertia>
        </inertial>
        <collision name='collision'>
          <geometry>
            <box>
              <size>2 1 0.3</size>
            </box>
          </geometry>
        </collision>
        <visual name='visual'>
          <!-- <pose>0 0 0.05 0 0 0</pose> This was for the mesh thing-->
          <geometry>
            <box>
              <size>2 1 0.3</size>
            </box>
            <!--
            <mesh>
              <uri>model://pioneer2dx/meshes/chassis.dae</uri>
              <scale>0.9 0.5 0.5</scale>
            </mesh>
            -->
          </geometry>
        </visual>
      </link>

      <!-- Inserting the front left wheel -->           
      <link name='front_left_wheel'>
        <pose>0.8 0.6 0.125 0 1.5707 1.5707</pose>
        <collision name='collision'>
          <geometry>
            <cylinder>
              <radius>0.125</radius>
              <length>0.05</length>
            </cylinder>
          </geometry>
        </collision>
        <visual name='visual'>
          <geometry>
            <cylinder>
              <radius>0.125</radius>
              <length>0.05</length>
            </cylinder>
          </geometry>
        </visual>
      </link>

      <!-- Inserting the front right wheel -->           
      <link name='front_right_wheel'>
        <pose>0.8 -0.6 0.125 0 1.5707 1.5707</pose>
        <collision name='collision'>
          <geometry>
            <cylinder>
              <radius>0.125</radius>
              <length>0.05</length>
            </cylinder>
          </geometry>
        </collision>
        <visual name='visual'>
          <geometry>
            <cylinder>
              <radius>0.125</radius>
              <length>0.05</length>
            </cylinder>
          </geometry>
        </visual>
      </link>
      
      <!-- Inserting the rear left wheel -->           
      <link name='rear_left_wheel'>
        <pose>-0.8 0.6 0.125 0 1.5707 1.5707</pose>
        <collision name='collision'>
          <geometry>
            <cylinder>
              <radius>0.125</radius>
              <length>0.05</length>
            </cylinder>
          </geometry>
        </collision>
        <visual name='visual'>
          <geometry>
            <cylinder>
              <radius>0.125</radius>
              <length>0.05</length>
            </cylinder>
          </geometry>
        </visual>
      </link>

      <!-- Inserting the rear right wheel -->           
      <link name='rear_right_wheel'>
        <pose>-0.8 -0.6 0.125 0 1.5707 1.5707</pose>
        <collision name='collision'>
          <geometry>
            <cylinder>
              <radius>0.125</radius>
              <length>0.05</length>
            </cylinder>
          </geometry>
        </collision>
        <visual name='visual'>
          <geometry>
            <cylinder>
              <radius>0.125</radius>
              <length>0.05</length>
            </cylinder>
          </geometry>
        </visual>
      </link>

      <!-- Adding a Laser Sensor (hokuyo) -->
      <!-- Or a Camera -->
      <include>
        <!-- <uri>model://hokuyo</uri> -->
        <uri>model://camera</uri>
        <pose>0.2 0 0.5 0 0 0</pose>
      </include>
      <joint name='hokuyo_joint' type='fixed'>
        <child>hokuyo::link</child>
        <parent>chassis</parent>
      </joint>

      <!-- Connecting each wheel to the chassis -->
      <joint type='revolute' name='f_left_wheel_hinge'>
        <pose>0 0 -0.03 0 0 0</pose>
        <child>front_left_wheel</child>
        <parent>chassis</parent>
        <axis>
          <xyz>0 1 0</xyz>
        </axis>
      </joint>

      <joint type='revolute' name='f_right_wheel_hinge'>
        <pose>0 0 0.03 0 0 0</pose>
        <child>front_right_wheel</child>
        <parent>chassis</parent>
        <axis>
          <xyz>0 1 0</xyz>
        </axis>
      </joint>

      <joint type='revolute' name='r_left_wheel_hinge'>
        <pose>0 0 -0.03 0 0 0</pose>
        <child>rear_left_wheel</child>
        <parent>chassis</parent>
        <axis>
          <xyz>0 1 0</xyz>
        </axis>
      </joint>

      <joint type='revolute' name='r_right_wheel_hinge'>
        <pose>0 0 0.03 0 0 0</pose>
        <child>rear_right_wheel</child>
        <parent>chassis</parent>
        <axis>
          <xyz>0 1 0</xyz>
        </axis>
      </joint>

  </model>
</sdf>
